Workbook

Sheet 04.01-04.07
B1: hétfő 1 | C1: kedd 2 | D1: szerda 3 | E1: csütörtök 4 | F1: péntek 5 | G1: szombat 6 | H1: vasárnap 7
B2: 109/11715-1003 Rácalmás | C2: 109/11715-1002 Rácalmás | D2: 100/1601-1503 Siófok | E2: 100/1600-3010 Adony | F2: 100/1600-3018 Dföldvár
B3: 109/11861-365 Szd | C3: 100/1600-3011 Adony | E3: 100/1600-3012 Paks | F3: 100/1600-2983 Dföldvár
B4: 100/1599 | F4: 100/1600-3017 Asztiván
A5: Ford
A6: NGM157
A8: Név | B8: Galág-Tolnai | C8: Galág-Tolnai | D8: Galág-Tolnai | E8: Staudt-Tolnai | F8: Galág-Tolnai
B9: 100/1601-1498 Siójut | C9: 100/1608- Őcsény | D9: 100/1599 Eon léges | E9: 100/1608 Nagyszokoly | F9: 100/1601-1495 Varga
E10: 100/1608 Nagyszokoly
D11: 13 óra 90000-s szerviz | E11: 100/1608 Nagyszokoly
A12: Ford | E12: 100/1608 Nagyszékely
A13: NGM158
A15: Név | B15: Jókai-Klieber | C15: Jókai-Klieber | D15: Staudt -Kunfalvi | E15: Jókai-Klieber | F15: Jókai-Klieber
C16: 100/1600-3003 Nagydorog | D16: 109/11861-366 Szd | F16: 113/10058 utólgos TECHNO
C17: 113/10057 Paks | D17: 109/11861-367 Decs | F17: 18 db
B18: 113/10057 Paks | D18: 100/1608-657 Tolna | E18: 1/2 8 szerviz
A19: Dacia | F19: 113/10059 Decs
A20: LSX504 | B20: 100/1600-2992 Dújv 12 óra
A22: Név | B22: Erős-Pilisi | C22: Erős-Pilisi | D22: Erős-Pilisi | E22: Kunfalvi | F22: Erős-Pilisi
B23: Paks PSE | C23: Pécs | D23: Pécs | E23: Pécs | F23: 100/1600-3014 Szd
F24: 100/1599 Eon léges
A26: Dacia
A27: LTZ294
A29: Név | B29: Balogh-Staudt | C29: Balogh | D29: Balogh | E29: Balogh | F29: Staudt - Kunfalvi
D30: 100/1600-3007 Paks | E30: 109/11861-368 Szd
D31: 100/1600-3008 Nagydorog | E31: 100/1600-2992 Dújv
D32: 100/1600-3009 Szekszárd
A33: Mazda
A34: JZA908
A36: Név | D36: Jókai-Klieber | E36: Erős-Pilisi
C37: 100/1601-1501 Siófok | D37: Kaposvár | E37: Budapest
C38: 100/1601-1502 Siófok
C39: 100/1601-1504 Siófok
A40: SUZUKI
A41: NCH903
A43: Név | C43: Staudt-Kunfalvi | D43: Zsuzsa | E43: Zsuzsa-Galág-Rajkó
A44: VW
A45: PUU152
A47: Név
E48: Galág | F48: Balogh
...

Sheet 04.08-04.14
B1: hétfő 04 .08. | C1: kedd 04. 09. | D1: szerda 04.10. | E1: csütörtök 04. 11. | F1: péntek 04. 12. | G1: szombat 13 | H1: vasárnap 14
B2: GPS ellenőrzés | C2: 109/11715-1008 Dújv 10 | D2: 100/1600-3006 Rácalmás | E2: 109/11715-1006 Nvenyim 11 | F2: 100/1600-3005 Adony
B3: 100/1608-661 Kulcs | C3: 100/1600-3021 Dújváros | D3: 109/11715-1005 Dújv 10 | E3: 100/1600-3016 Rácalmás 13 | F3: 109/11715-1007Nvenyim 10
B4: 100/1608-649 Dújv | C4: 100/1600-3020 Dújváros | D4: 109/12098 Perkáta 11 | E4: 100/1600-2999 Tolna | F4: 109/11861-376 Paks Ip.park
A5: Ford | B5: 100/1608-656 Tolna-Mözs | C5: 100/1600-2983 Dföldvár | F5: 109/11861-377 Paks Munk.10
A6: NGM157
A8: Név | B8: Galág-Tolnai | C8: Galág - Tolnai | D8: Galág - Tolnai | E8: Galág - Tolnai | F8: Galág - Tolnai
B9: GPS ellenőrzés | C9: 100/1608-663 Dunaföldvár (du.) | D9: Paks Erőmű | E9: 100/1601-1507 Siófok | F9: 100/1601-1509 Ságvár
B10: 100/1601-1500 B.szárszó | C10: 100/1608-664 Sárbogárd (1) | E10: 100/1601-1508 Siófok | F10: 100/1600-3023 Simontornya
A11: Ford | B11: 100/1601-1505 Siófok | C11: 100/1608-665 Paks | E11: 100/1608-652 Nagyszokoly | F11: 100/1601-Balatonszabadi 9
A12: NGM158 | B12: 100/1601-1489 Siófok 13:00 | C12: 100/1608-671 Szd | E12: 100/1608-653 Nagyszokoly
E13: 100/1608-654 Nagyszokoly
C14: 100/1608-629 Fadd
A15: Név | B15: Jókai-Klieber | C15: Jókai-Klieber | D15: Staudt | E15: Jókai-Klieber | F15: Staudt-Klieber
B16: GPS ellenőrzés | C16: 109/11861-369 Pincehely | D16: 109/12103 Paks | E16: 100/1608- Váralja | F16: 113/10058 utólagos TECHNO
C17: 109/11861-370 Simontornya | D17: 100/1600-3026 Várdomb 8 | E17: 100/1608- Váralja
A18: Dacia | B18: 100/1608-659 Máza 8:30 | C18: 109/11861-371 Zomba | D18: 109/11861-375 Fácánkert | E18: 100/1608-658 Bonyhád
A19: LSX504 | B19: 100/1608-660 Máza 9:30 | C19: 109/11861-372 Tolnanémedi | D19: 109/11861-374 fadd-Dombori | E19: 100/1608-668 Fácánkert
B20: 100/1608-662 Döbrököz | C20: 109/11861-373 Tolnanémedi | E20: 100/1608-669 Fácánkert
A22: Név | B22: Erős-Kunfalvi | C22: Erős - Staudt | D22: Erős-Kunfalvi | E22: Erős-Kunfalvi | F22: Erős-Pilisi
B23: GPS ellenőrzés | C23: Pécs | D23: Pécs | E23: Pécs | F23: Pécs
A25: Dacia | B25: 100/1599 Eon léges
A26: LTZ294
A29: Név | B29: Staudt | C29: Balogh | D29: Balogh | E29: Balogh | F29: Balogh
E30: 100/1608-666 Sárszentlőrinc | F30: 101 Baja cövek
D31: 100/1608-670 Szd 8:00 | E31: 100/1608-667 Sárszentlőrinc
A32: Mazda | D32: 100/1608-668 Fácánkert | E32: 100/1608-675 Sárszentlőrinc
A33: JZA908 | D33: 100/1608-669 Fácánkert | E33: 100/1608-665 Paks 12:00
D34: Paks IpariPark 10:00 | E34: 100/1608-664 Sárbogárd (du)
D35: 100/1608- Tolna
A36: Név | D36: Jókai-Klieber | E36: Staudt-Pilisi | F36: Kunfalvi
A38: SUZUKI
A39: NCH903
A41: Név
A43: VW
A44: PUU152
A45: Név
B46: Pilisi | C46: Pilisi | D46: Pilisi | F46: Jókai
B47: Balogh | C47: Kunfalvi
A49: Magyarázat: | B49: Munkanapló hiányzik!!!

Sheet 04.15-04.21
B1: hétfő 04 .15. | C1: kedd 04. 16. | D1: szerda 04.17. | E1: csütörtök 04. 18. | F1: péntek 04. 19. | G1: szombat 20 | H1: vasárnap 21
B2: 100/1600-3028 Sárbogárd | C2: 100/1600-3023 Simontornya | D2: 109/11715- 1016 Kocsola 10 | E2: 109/12091-3 Gyulaj
C3: 100/1608-674 Tamási ipari park | D3: 109/11715-1015 Döbrököz 13 | E3: 109/11715-1014 Kszekcső 10
C4: 100/1601-1503 Siófok | D4: 100/1608-655 Nagyszékely | E4: 109/11715-1017 Dombóvár 13
A5: Ford | C5: 100/1608-525 Tamási ?????
A6: NGM157
A8: Név | B8: Galág - Tolnai | C8: Galág - Tolnai | D8: Galág - Tolnai | E8: Galág - Tolnai
B9: 109/11715-1009 Bonyhád 9 | C9: 100/1600-3024 Kulcs | D9: 109/11715-1011 Bonyhád 12 | E9: 100/1600-3025 Kulcs
B10: 109/11715-1010 Bonyhád 11 | D10: 109/11715-1012 Bonyhád 9 | E10: 109/12106 Paks 8
A11: Ford | B11: 100/1600-3013 Tolna | D11: 100/1599 | E11: 100/1600-2991 Dújváros
A12: NGM158 | B12: 100/1600-3029 Bonyhádvarasd | E12: 100/1600-3006 Rácalmás
A15: Név | B15: Jókai - Klieber | C15: Jókai - Klieber-Pilisi | D15: Jókai | E15: Jókai-Pilisi
B16: Gumi | C16: 109/11715-1013 Bonyhád 11 | D16: 109/11715-1018 Mohács 10 | E16: 113/10058 utólagos 4db
B17: 109/12104 Zamárdi | C17: 100/1608-677 Fadd-dombori (4) | D17: 109/11715-1019 Mohács 12 | E17: 100/1608-678
A18: Dacia | B18: 100/1601-1507 Siófok | C18: 100/1608-659 Máza 10:00 (2) | D18: 100/1600-3027 Báta 8 | E18: 100/1608-664-Sárbogárd (1)
A19: LSX504 | C19: 100/1608-660 Máza 10:30 (3) | D19: 100/1599
C20: 100/1608-671 Szekszárd
C21: 100/1608-670 Szekszárd
A23: Név | B23: Erős-Kunfalvi | C23: Erős-Kunfalvi | D23: Erős-Kunfalvi | E23: Erős-Kunfalvi
B25: 100/1608-671 Szekszárd | C25: Pécs | D25: Pécs | E25: Pécs
A26: Dacia | B26: 100/1608-670 Szekszárd
A27: LTZ294 | B27: 100/1608-665 Paks
A30: Név | B30: Balogh | C30: Balogh | D30: Balogh | E30: Balogh
B31: 100/1600-3019 Hidas | D31: 100-1600-3034 Darusztmiklós
A32: Mazda | B32: 110/10087 Paks PSE 8 | D32: 100/1608-664-Sárbogárd (1)
A33: JZA908 | B33: 109/11861-378-Szekszárd | D33: 100/1600-3022 Sársztágota
D34: 109/12091-3 Sárbogárd
D35: 100/1606 Nagyvenyim üz
A37: Név | B37: Staudt-Pilisi | D37: Pilisi - Klieber
B38: Műszaki vizsga! | C38: Baja | E38: Dunaszetngyörgy
A39: SUZUKI
A40: NCH903
A42: Név | B42: Kulcsár L. | C42: Kulcsár L. | E42: Kulcsár L.
A43: VW
A44: PUU152
A45: Név
C46: Staudt | D46: Staudt | E46: Klieber
E47: Staudt
A48: Magyarázat: | B48: Munkanapló hiányzik!!!

Sheet 04.22-04.28
B1: 2019-04-hétfő 22 | C1: kedd 23 | D1: szerda 24 | E1: csütörtök 25 | F1: péntek 26 | G1: szombat 27 | H1: vasárnap 28
C2: 100/1599 | D2: 100/1600-3034 Darúsztmiklós | E2: 109/11715-1022 Kulcs 11
C3: 109/12091-3 SMHV | D3: 109/11715-1020 Dújváros 11 | E3: 100/1600-3031 Kulcs
D4: 100/1600-3031 Kulcs
A5: Ford
A6: NGM157
A8: Név | C8: Galág-Pilisi | D8: Galág-Tolnai | E8: Galág-Tolnai
C9: 100/1601-1507 Siófok | D9: 100/1601-1517 Tamási | E9: 111/10008 Szalksztmárton | F9: 109/11715-1023 Sáregres 10
C10: 100/1601-1515 Siófok | D10: 100/1601-1515 Siófok | F10: 100/1600-3022 Sársztágota
F11: 100/1600-3024 Kulcs
A12: Ford
A13: NGM158
A15: Név | C15: Jókai-Klieber | D15: Jókai-Klieber | E15: Jókai-Klieber | F15: Jókai-Klieber
C16: 100/1600-3035 Szegyháza | D16: 100/1600-3027 Báta | E16: 100/1608-Váralja | F16: 113/10058 utólagos
D17: 100/1600-3035 Szegyháza | E17: 100/1608-Váralja | F17: 100/1608-Sársztlőrinc
D18: Bátaszék | E18: 100/1608-Sársztlőrinc | F18: 100/1608-Sársztlőrinc
A19: Dacia | E19: 100/1608-Sársztlőrinc
A20: LSX504
A22: Név | C22: Erős-Staudt-Balogh | D22: Erős-Kunfalvi | E22: Erős-Kunfalvi | F22: Erős-Kunfalvi
D23: Pécs | E23: Pécs | F23: Pécs
A26: Dacia
A27: LTZ294
A29: Név | D29: Balogh | E29: Balogh | F29: Balogh
D30: 100/1600-3035 Szegyháza | E30: Paks PSE | F30: 100/1600-3035 Szegyháza
E31: 100/1599 Eon léges
A33: Mazda
A34: JZA908
A36: Név | D36: Staudt-Pilisi | E36: Staudt-Pilisi | F36: Staudt-Pilisi
E37: 100/1642 Bácsalmás
A39: SUZUKI
A40: NCH903
A42: Név | E42: Iván Zs.
A43: VW
A44: PUU152
A46: Név
C47: Tolnai | F47: Galág
C48: Kunfalvi | F48: Tolnai
A51: Magyarázat: | B51: Munkanapló hiányzik!!!

Sheet 04.29-05.05
A1: 18. hét | B1: hétfő 04.29 | C1: kedd 04.30 | D1: szerda 05.01 | E1: csütörtök 05.02 | F1: péntek 05.03 | G1: szombat 05.04 | H1: vasárnap 05.05
B2: Magyarszék víztározó | C2: 109/11715-1025 Pusztaszabolcs | E2: 109/11715-1015 Döbrököz 12 | F2: 113/10060 utólagos
C3: 109/11715-1026 Pusztaszabolcs | E3: 109/11715-1016 Kocsola 9
A4: Ford | C4: 100/1600-3033 Kulcs | E4: 100/1601-1518 Siófok
A5: NGM157 | C5: 109 Paks Fh | E5: 100/1608-674 Tamási
A7: Név | B7: Balogh | C7: Galág-Klieber | E7: Galág-Tolnai | F7: Kunfalvi-Tolnai
B8: 109/11715-1024 Paks | C8: 100/1600-3024 Kulcs
B9: 100/1600-3029 Bonyhádvarasd
A10: Ford | B10: 110/10087 Paks PSE
A11: NGM158 | B11: 109/12110 Paks
A14: Név | B14: Jókai-Pilisi | C14: Jókai-Pilisi
B15: 109/12107 Cece 8 | C15: 100/1600-3032 Kulcs | E15: 100/1600-3037 Adony 9 | F15: 109/11861-379 Tolna 8
B16: 109/12108 Sárbogárd | C16: 100/1599 Bátaszék 7:45 | E16: 100/1608-543 Dunaújv Farkas 11:00 | F16: 109/11861-380 Fadd-Domb. 9
A17: Dacia | C17: 100/1608-Sárszentlőrinc | E17: 100/1600-3036 Dunaújváros | F17: 109/11861-381 Fadd 10
A18: LSX504
A20: Név | B20: Erős-Kunfalvi | C20: Erős-Kunfalvi | E20: Erős-Kunfalvi-Pilisi | F20: Pilisi-Ritter
B21: 100/1601-1516 Zamárdi 10 | C21: Pécs | E21: Pécs | F21: Pécs
B22: 100/1601-1515 Siófok
A23: Dacia
A24: LTZ294
A27: Név | B27: Galág-Klieber | C27: Balogh | E27: Balogh | F27: Balogh
A30: Mazda
A31: JZA908
A34: Név
A37: Suzuki
A38: NCH903
A40: Név
A42: VW
A43: PUU152
A44: Név
A45: Szabadság | E45: Jókai | F45: Jókai Erős Galág
A46: Beteg | B46: Tolnai | C46: Tolnai | E46: Klieber | F46: Klieber
A48: Magyarázat: | B48: Munkanapló hiányzik!!!
A49: munka stornó

Sheet 05.06-05.12
A1: 19. hét | B1: hétfő 05.06 | C1: kedd 05.07 | D1: szerda 05.08 | E1: csütörtök 05.09 | F1: péntek 05.10 | G1: szombat 05.11 | H1: vasárnap 05.12
B2: 100/1600-3038 Sárbogárd | D2: 109/11715-987 Rácalmás 13 | E2: 109/11715-1028 Szálka 10 | F2: 109/11715-1029 Tolna 12
B3: 100/1600-3039 Sárosd | D3: 100/1599-2-35 Eon léges | E3: 109/11861-386 Szeksz. 8 | F3: 109/11715-1030 Nagymányok 9
A4: Ford | B4: 100/1599 Eon léges | D4: 100/1600-2983 Dunaföldvár | E4: 100/1600-3040 Aparhant | F4: 113/10060 utólagos Györe
A5: NGM157 | B5: szerviz ? Sárga lámpa | D5: 100/1600-2965 Dunaújváros
A7: Név | B7: Galág-Tolnai | D7: Galág-Tolnai | E7: Galág-Tolnai | F7: Galág-Pilisi
B8: 100/1600-3030 Kulcs | C8: 109/11861-383 Dsztgyörgy 8 | D8: 100/1600-3033 Kulcs | E8: 100/1600-3032 Kulcs | F8: 100/1600- ? Kulcs
C9: 109/11861-384 Paks 10 | D9: 100/1600-3032 Kulcs | E9: 100/1600-3007 Paks | F9: Darusztmiklós
A10: Ford | B10: 100/1608-661 Kulcs | C10: 109/11861-385 Paks 10
A11: NGM158 | B11: 109/11861-383 Dsztgyörgy 8 | C11: 100/1600-3030 Kulcs
B12: 109/11861-384 Paks 10 | C12: 110/10087 Paks PSE 8
B13: 109/11861-385 Paks 10
A14: Név | B14: Jókai Pilisi | C14: Jókai Pilisi Tolnai | D14: Jókai Erős Kunfalvi | E14: Jókai- Kunfalvi | F14: Jókai-Balogh
B15: 100/1608-684 Nagyvenyim | C15: 109/12105 Szálka 8 | E15: 111/10010 Dunaföldvár | F15: 113/10060 utólagos Sárbogárd (1)
B16: Szekszárd Kajak 8:00 | C16: 100/1600-2966 Szd | E16: 100/1608-669 Fácánkert 11:00 | F16: 100/1608-661 Kulcs (2) 11:30 kb
A17: Dacia | B17: 100/1608-683 Nagyvenyim | C17: 100/1608-610 Bátaszék | E17: 100/1608-676 Dunaújváros | F17: 100/1608-580 Bölcske
A18: LSX504 | B18: 100/1608-665 Paks | F18: 100/1608-695 Bölcske
B19: 100/1608-543 Dunaújváros
A20: Név | B20: Erős-Kunfalvi | C20: Erős-Kunfalvi | E20: Erős | F20: Erős-Kunfalvi
B22: Pécs
A23: Dacia
A24: LTZ294
A26: Név
A29: Mazda
A30: JZA908
A33: Név
B34: 100/1601-1518 Siófok | C34: 100/1600-3043 Kajdacs 10 | D34: 100/1608-686 Tamási | E34: 109/12111 Balatonöszöd
B35: 100/1608- | C35: 109/11715-1027 Kulcs 14 | D35: 100/1600-3001 Hőgyész 9 | E35: 100/1601-1489 Siófok
A36: Suzuki | B36: Szekszárd kitűzés Remete 7:45 | C36: 100/1599-2-35 Eon léges | D36: 100/1608-685 Regöly
A37: NCH903 | C37: 100/1600-3044 Fácánkert 9 | D37: 100/1608-674 Tamási
D38: 100/1608-687 Nagykónyi
A39: Név | B39: Balogh-Klieber | C39: Balogh-Klieber | D39: Balogh-Pilisi | E39: Balogh-Pilisi
A41: VW
A42: PUU152
A43: Név
A44: Szabadság | D44: Klieber | E44: Klieber | F44: Klieber Tolnai
A45: Beteg | C45: Galág
A47: Magyarázat: | B47: Munkanapló hiányzik!!!

Sheet 05.13-05.19
A1: 20. hét | B1: hétfő 05.13 | C1: kedd 05.14 | D1: szerda 05.15 | E1: csütörtök 05.16 | F1: péntek 05.17 | G1: szombat 05.18 | H1: vasárnap 05.19
B2: 100/1601-1522 Nagyszokoly 11 | E2: 100/1601-1518 Siófok | F2: 109/11715-1032 Dombóvár 9
B3: 100/1601-1518 Siófok | D3: eső | E3: 100/1601-1528 Bföldvár | F3: 100/1601-1520 Siófok
A4: Ford | F4: 100/1600-1480 Siófok
A5: NGM157 | F5: 100/1601-1527 Regöly
F6: 100/1608-685 Regöly ?
A7: Név | B7: Balogh-Tolnai | D7: Balogh-Tolnai | E7: Balogh-Tolnai | F7: Balogh-Tolnai
B8: 100-1600-3030 Kulcs | C8: 100/1608-688 Iregszemcse | E8: 109/12115 Bátaapáti | F8: 109/12115 Bátaapáti
C9: 100/1608-689 Iregszemcse | F9: 110/10087 Paks PSE 8
A10: Ford | C10: 100/1608-696 Tamási | F10: Paks, Anna u. földkábel (100m)
A11: NGM158 | C11: 100/1608-687 Nagykónyi | D11: eső
C12: 100/1608-691 Tolnanémedi
A14: Név | B14: Jókai Klieber-oltás7:45 | C14: Jókai - Klieber-Tolnai | D14: Jókai Klieber | E14: Galág-Jókai | F14: Jókai-Galág
B15: 109/12110 Paks | C15: 100/1600-3045 Dunaújváros | E15: 100/1608-690 Pincehely | F15: 109/11861-387 Szekszárd 8
B16: 100/1600-3007 Paks | C16: 109/12112 Sárosd 9:30 | E16: 100/1608-693 Szakály | F16: 109/11715-1035 Várdomb 9
A17: Dacia | B17: 109/12091-3 Paks | C17: 109/*12107 Cece | D17: eső | E17: 100/1608-692 Tamási | F17: 113/10060 utólagos
A18: LSX504 | B18: 100/1608-454 Fácánkert 8:00 | E18: 100/1608-694 Hőgyész | F18: 109/11861-390 Szekszárd 8
E20: 100/1600-3047 Kisapostag
A21: Név | B21: Erős-Kunfalvi | C21: Erős-Kunfalvi | D21: Erős-Kunfalvi | E21: Erős-Kunfalvi | F21: Erős-Kunfalvi
A24: Dacia | D24: 0
A25: LTZ294
A28: Név
A31: Mazda
A32: JZA908
A35: Név
B36: 109/11715-1033 Bonyhád 8 | C36: 100/1600-3033 Kulcs | E36: GINOP továbbképzés | F36: GINOP továbbképzés
B37: 109/11715-1015 Döbrököz 13 | C37: 100/1599 Eon léges
A38: Suzuki | B38: 100/1599 Eon léges | D38: eső
A39: NCH903
A41: Név | B41: Galágh-Pilisi | C41: Galágh-Pilisi | D41: Galágh-Pilisi | E41: Kulcsár L. | F41: Kulcsár L.
A43: VW
A44: PUU152
A45: Név
A46: Szabadság
A47: Beteg | C47: Balogh
A48: Távollét | E48: Klieber-Pilisi oktatás | F48: Klieber-Pilisi oktatás
A50: Magyarázat: | B50: Munkanapló hiányzik!!!

Sheet 05.20-05.26
A1: 21. hét | B1: hétfő 05.20 | C1: kedd 05.21 | D1: szerda 05.22 | E1: csütörtök 05.23 | F1: péntek 05.24 | G1: szombat 05.25 | H1: vasárnap 05.26
B2: 100/1638 Magyarszék | D2: 100/1600-3042 Györköny | E2: 109/11715-1044 Dszekcső 11 | F2: 109/11715-1045 Hháza 12
B3: 100/1600-3046 Bonyhád | E3: 109/11861-393 Szekszárd | F3: 100/1638 Magyarszék
A4: Ford | E4: 109/11861-378 Szekszárd
A5: NGM157 | E5: 109/11861-388 Szekszárd
E6: 109/11861-392 Szekszárd
E7: 109/11861-391 Szekszárd
E8: 109/11861-390 Szekszárd
E9: 109/11861-394 Szekszárd 8
E10: 109/11861-395 Szekszárd 10
A11: Név | B11: Balogh-Tolnai | D11: Balogh-Tolnai | E11: Balogh-Tolnai | F11: Balogh-Tolnai
B12: 110/10087 Paks PSE | C12: 110/10113 Darúszentmiklós | D12: 100/1608-580 Bölcske | E12: 100/1601-1480 Siófok | F12: 109/12118 Paks 13
B13: 110/10087 Paks PSE | C13: 100/1600-3042 Györköny | D13: 100/1608-695 Bölcske | E13: 113/10061 Szd 8:00 | F13: 109/11715-1040 Paks 9
A14: Ford | E14: 100/1608-685 Regöly | F14: 109/12113 Dsztgyörgy
A15: NGM158 | E15: 100/1601-1528 Siófok 10
F16: 100/1601-1528 Siófok ?
A18: Név | B18: Jókai-Klieber | C18: Jókai-Klieber | D18: Jókai-Klieber | E18: Jókai-Klieber | F18: Jókai-Klieber
B19: 109/11715-1028 Szálka 10 | C19: 109/11715-1041 Paks 9 | D19: 100/1600-3041 Decs | E19: 109/12116 Dunaföldvár
B20: 109/11715-1036 Szálka 12 | C20: 109/11715-1042 Paks 11 | D20: 109/12114 Bátaszék | E20: 109/11715-1039 Dunaújváros 10 | F20: 113/10060 utólagos 7db
A21: Dacia | B21: 109/12112 Sárosd 11 | C21: 109/11715-1043 Paks 13 | E21: 100/1608-699 Dunaújváros 14 | F21: 100/1608-704 Szekszárd
E22: 109/12091-4 SMHV | F22: 100/1608-688 Iregszemcse
A23: LSX504 | B23: 109/12091-4 | C23: 109/12109 Paks | E23: 109/12109 Paks Anna | F23: 100/1608-689 Iregszemcse
B24: 100/1599
A25: Név | B25: Galág-Pilisi | C25: Erős- Tolnai | D25: Erős- Kunfalvi | E25: Erős- Kunfalvi | F25: Galág-Kunfalvi
A28: Dacia
A29: LTZ294
A32: Név
B33: 100/1634 OKTM kitűzés | F33: 100/1599 Eon léges
B34: Bátaszék, Szekszárd, Medina
A35: Mazda
A36: JZA908
A39: Név | B39: Erős- Kunfalvi | F39: Pilisi
C40: 109/11715-1037 Rácalmás 9 | D40: 109/11715 Nagyvenyim 10 | E40: 100/1601-1529 Köröshegy | F40: IRM továbbképzés
C41: 109/11715-1038 Besnyő 12 | D41: 109/12102 Paks | E41: 100/1601-1527 Tamási | F41: Iván Zs.
A42: Suzuki | C42: 100/1608-697 Dunaújváros 14 | D42: 100/1608-698 Dunaújváros 14 | E42: 100/1601-1482 Tamási 9 | F42: Erős J.
A43: NCH903 | C43: 109/12091-4 SMHV | D43: 109/12091-4 SMHV | E43: 100/1600-3038 Sárbogárd 11
A45: Név | C45: Galág-Pilisi | D45: Galág-Pilisi | E45: Galág-Pilisi | F45: Kulcsár L
A47: VW
A48: PUU152
A49: Név
...

Sheet 05.27-06.02
A1: 22. hét | B1: hétfő 05.27 | C1: kedd 05.28 | D1: szerda 05.29 | E1: csütörtök 05.30 | F1: péntek 05.31 | G1: szombat 06.01 | H1: vasárnap 06.02 | I1: májusban
B2: 100/1638 Magyarszék | C2: 100/1638 Magyarszék | D2: 100/1638 Magyarszék | E2: 100/1638 Magyarszék | F2: 109/11715-1011 Bonyhád 12
A4: Ford | F4: 100/1600-3046 Bonyhád
A5: NGM157 | F5: 109/11861-398 Szekszárd 8
F6: 109/11861-399 Fadd-Dombori 12
A7: Név | B7: Balogh-Tolnai | C7: Balogh-Tolnai | D7: Balogh-Tolnai | E7: Balogh-Tolnai | F7: Balogh-Tolnai
B8: ERŐMŰ | C8: ERŐMŰ | D8: ERŐMŰ | E8: Paks bazársor és orvosi rendelő | F8: 100/1601-1531 Koppányszántó
E9: szkenneres felmérése | F9: 100/1608-685 Regöly
A10: Ford | F10: 100/1608-709 Szakály
A11: NGM158 | F11: 100/1601-1482 Tamási
A14: Név | B14: Jókai-Steinbach | C14: Jókai-Steinbach | D14: Jókai-Steinbach | E14: Jókai-Hajpál | F14: Jókai-Klieber
B15: 109/12106 Paks Ősz | C15: 100/1608-687 Nagykónyi | D15: 109/11715-1050 Fadd 9 | E15: 109/12091-4 SMHV | F15: 113/10060 utólagos
B16: 109/12109 Paks Anna | C16: 100/1608-691 Tolnanémedi | D16: 100/1601-1528 Balatonföldvár | E16: 100/1600-3008 Nagydorog 8 | F16: 109/11715-1049 Nagyvenyim 9
A17: Dacia | B17: 100/1608-606 Sárbogárd ? | C17: 100/1608-696 Tamási | D17: 100/1608-708 Fácánkert | E17: 109/12106 Paks Ősz | F17: 100/1608-705 Szekszárd
A18: LSX504 | C18: 100/1601-1517 Tamási SOS | E18: 109/12109 Paks Anna
A20: Név | B20: Erős | C20: Erős | D20: Erős | E20: Erős-Klieber | F20: Erős-Pilisi
A21: Dacia
A22: LTZ294
A23: Név
E24: 100/1608-701 Dunaújváros ???
E25: 100/1600-3049 Hantos
A26: Mazda | E26: 100/12091-4 SMHV
A27: JZA908
A29: Név | E29: Galág-Pilisi
B30: 109/12091-4 SMHV | C30: 100/1608-707 Dunaújváros 8:15 | D30: 100/1608-700 Dunaújváros 14 | E30: Balatonalmádi | F30: Balatonalmádi
B31: 100/1599 Eon léges | C31: 109/11715-1047 Rácalmás 13 | D31: 100/11715-1046 Baracs 9
A32: Suzuki | C32: 109/11715-1055 Bölcske | D32: 100/11715-1048 Baracs 11
A33: NCH903 | B33: 113/10062 Paks 8:00 | C33: 100/11715-1046 Baracs 9 | D33: 100/1600-3047 Kisapostag
C34: 100/11715-1048 Baracs 11 | D34: 109/11861-396 Németkér 8
D35: 109/11861-397 Németkér 10
A37: Név | B37: Galág-Klieber | C37: Galág-Klieber | D37: Galág-Klieber | E37: Kulcsár L. | F37: Kulcsár L. | I37: 1
B38: Villány
A39: VW
A40: PUU152
A41: Név | B41: Kulcsár L.
A42: Szabadság | B42: Pilisi Kunfalvi | C42: Pilisi Kunfalvi | D42: Pilisi Kunfalvi | E42: Kunfalvi | F42: Kunfalvi Galág
A43: Beteg
A44: Távollét
A45: Magyarázat: | B45: Munkanapló hiányzik!!! | H45: Összesen : | I45: =SUM(I1:I44) -> 1

Sheet 06.03-06.09
A1: 23. hét | B1: hétfő 06.03 | C1: kedd 06.04 | D1: szerda 06.05 | E1: csütörtök 06.06 | F1: péntek 06.07 | G1: szombat 06.08 | H1: vasárnap 06.09 | I1: júniusban
B2: 100/1600-3048 Dunaújváris | C2: 109/11715-1062 Ófalu 9 | D2: 109/11715-1009 Bonyhád 9 | E2: 109/11715-892 Mohács 9 | F2: 109/11715-1052 Rácalmás 10
C3: 109/11715-1063 Ófalu 10 | D3: 100/1608-710 Sióagárd | E3: 100/1600-3050 Véménd | F3: 109/11715-1061 Dunaújváros 12
A4: Ford | C4: 109/11861- Szd 3db | D4: 109/11861- Szd | F4: 109/11715-1064 Rácalmás 13
A5: NGM157 | D5: 109/11861-402 Dombori | F5: 109/11715-1060 Dunaföldvár 10
D6: Orvosi 7:45
A7: Név | B7: Balogh-Tolnai | C7: Balogh-Tolnai | D7: Balogh | E7: Balogh-Tolnai | F7: Balogh-Tolnai
B8: 100/1608-705 Szekszárd du. | C8: 100/1608-711 Dunaföldvár | D8: 109/11715-1051 Cece 10 | E8: 100/1600-3051 Cece
B9: 100/1600-3052 Sárhatvan | C9: 109/12113 Dunaszentgyörgy | D9: 100/1600-3055 Dunaújváros | E9: 100/1608-706 Tamási
A10: Ford | B10: 100/1600-3054 Nagyvenyim | D10: 100/1600-3056 Dunaújváros | E10: 110/10087 Paks PSE 8
A11: NGM158 | B11: 100/1608-693 Szakály | C11: 113/ Zomba | D11: 100/1608-701 Dunaújváros 14:30
A14: Név | B14: Jókai Klieber | C14: Jókai Klieber | D14: Jókai Klieber | E14: Jókai Klieber
B15: 100/1600-3048 Dunaújváros | C15: 100/1600-3053 Dunaújváros 8:30 | D15: 109/11715-1057 Madocsa 11 | E15: 109/11715-1059 Nagyvenyim 10 | F15: Scen
B16: 109/11715-1053 Dunaföldvár 9 | C16: 109/11715-1054 Rácalmás 10 | D16: 109/11715-1058 Madocsa 12 | E16: 109/11715-1056 Sárosd 10
B17: 100/1608-707 Dunaújváros 14:00 | C17: 109/12106 Paks Völgy | D17: 100/1599 Eon léges | E17: 100/1599 Eon léges
A18: Dacia | B18: 109/11715-1065 Dunaföldvár 11 | C18: 109/12091-4 SMHV | D18: 100-11861-400 Szálka 12 | E18: 100/1608-701 Dunaújváros 8:30
A19: LSX504 | B19: 109/12109 Paks | D19: 100/1600-3053 Dunaújváros
D20: Orvosi 7:45
A21: Név | B21: Erős-Kunfalvi | C21: Erős-Kunfalvi | D21: Erős-Kunfalvi | E21: Erős-Kunfalvi | F21: Jókai Klieber | I21: 1
A22: Dacia
A23: LTZ294
A25: Név
D26: 100/1600-3035 Szabadegyháza | E26: 100/1600-3035 Szabadegyháza | F26: 100/1600-3035 Szabadegyháza
A28: Mazda
A29: JZA908
A31: Név | D31: Galág-Pilisi | E31: Galág-Pilisi | F31: Galág-Pilisi
B32: 100/1600-3035 Szabadegyháza | C32: 100/1600-3035 Szabadegyháza | F32: 113/10060 utólagos 6db
F33: 109/11861-401 Gyönk 8
F34: 100/1608-714 Bonyhád
A35: Suzuki
A36: NCH903
A38: Név | B38: Galág-Pilisi | C38: Galág-Pilisi | F38: Erős-Kunfalvi
A40: VW
A41: PUU152
A42: Név
A43: Szabadság | D43: Tolnai
A44: Beteg
A45: Távollét
H46: Összesen : | I46: =SUM(I2:I45) -> 1
A47: Magyarázat: | B47: Munkanapló hiányzik!!!

Sheet 06.10-06.16
A1: 24. hét | B1: hétfő 06.10 | C1: kedd 06.11 | D1: szerda 06.12 | E1: csütörtök 06.13 | F1: péntek 06.14 | G1: szombat 06.15 | H1: vasárnap 06.16 | I1: júniusban
C2: 113/10063 Dunaújváros | D2: 100/1638 Magyarszék | E2: 109/11715-1066 Dunaföldvár 10 | F2: Sportnap
E3: 109/11715-1067 Paks 9
A4: Ford | E4: 109/12120 Kulcs
A5: NGM157
A8: Név | C8: Galág-Tolnai | D8: Balogh-Tolnai | E8: Balogh-Tolnai-Új | I8: =+'06.03-06.09'!I7+1 -> 1
D9: 100/1608-674 Tamási | E9: Erőmű | F9: Sportnap
D10: 100/1601-1535 Zamárdi | E10: Darúszentmiklós
A11: Ford | D11: 100/1601-1533 Tamási | E11: 100/1600-3065 Kajdacs
A12: NGM158
A15: Név | D15: Jókai-Klieber | E15: Jókai- Klieber
C16: 109/12119 Mohács Fk kutatás 9 | F16: Sportnap
C17: 100/1600-3060 Mohács
C18: 100/1600- Hantos
A19: Dacia
A20: LSX504
A21: Név | C21: Erős
D22: 109/11715-1068-Simontornya 10 | E22: 109/11715-1044 Dunaszekcső P | F22: Sportnap
A23: Clió | D23: 100/1601-1531 Tab | E23: 100/1600-3059 Dunaszekcső
A24: RNB601 | D24: 100/1608-690 Pincehely
A27: Név | D27: Erős-Pilisi | E27: Erős-Kunfalvi
E28: 100/1601-1532 Balatonszárszó | F28: Sportnap
E29: 100/1601-1537 Siófok
A30: Clió | E30: 100/1601-1538 Zamárdi
A31: RNB602
A33: Név | E33: Galág-Pilisi
C34: 100/1601-1537-Zamárdi 1 | E34: Balatonboglár 100/1643 | F34: Sportnap
C35: 100/1601-1482-Tamási 2 | D35: 113/10063 Dunaújváros
A36: Suzuki | C36: 100/1608-690 Pincehely 3
A37: NCH903
A39: Név | C39: Pilisi-Klieber | D39: Galág-Kunfalvi | E39: Iván Zsuzsa
F40: Sportnap
A41: VW
A42: PUU152
A43: Név
A44: Szabadság | C44: Balogh
A45: Beteg | C45: Kunfalvi
A46: Távollét
A47: Magyarázat: | B47: Munkanapló hiányzik!!!
H48: Összesen : | I48: =SUM(I2:I47) -> 1

Sheet 06.17-06.23
A1: 25. hét | B1: hétfő 06.17 | C1: kedd 06.18 | D1: szerda 06.19 | E1: csütörtök 06.20 | F1: péntek 06.21 | G1: szombat 06.22 | H1: vasárnap 06.23 | I1: júniusban
B2: 100/1601-1447 Döbrököz | C2: 100/1601-1536 Zamárdi | D2: 100/1601-1543 Iregszemcse | E2: 100/1638 Magyarszék | F2: 100/1601-1547 Siófok 10
B3: 100/1638 Magyarszék | C3: 109/12108 Sárbogárd
A4: Ford
A5: NGM157
A7: Név | B7: Balogh-Klieber | C7: Balogh-Újváry-Klieber | D7: Balogh-Újváry-Klieber | E7: Balogh | F7: Balogh-Újváry | I7: =+'06.10-06.16'!I8 -> 1
E8: 100/1600-3062 Kulcs | F8: 100/1600-3066 Dunaújváros
E9: 110/10113 Darúszentmiklós | F9: 100/1600-3063 Dunaújváros
A10: Ford
A11: NGM158
A14: Név | E14: Jókai Klieber | F14: Jókai Klieber
A17: Dacia
A18: LSX504
A20: Név
B21: 100/1600-3061 Szekszárd 8 | C21: 100/1601-1539 Ádánd | D21: 109/12122 Nagymányok | E21: 100/1600-3070 Simontornya 9 | F21: 113/10063 Dunaújváros
B22: 100/1600-3058 Szekszárd | C22: 100/1601-1482 Tamási | E22: 100/1600-1541 Siófok | F22: 100/1608-710 Sióagárd
A23: Clió | B23: 109/11861-404 Szekszárd 9 | C23: Hőgyész | D23: 100/1600-3015 Szd | E23: 100/1601-1471 Pincehely | F23: 113/10060 utólagos 1db Dújv
A24: RNB602 | D24: 109/12106 Paks
A27: Név | B27: Erős-Kunfalvi | C27: Erős-Kunfalvi | D27: Erős-Kunfalvi | E27: Erős-Kunfalvi | F27: Erős-Kunfalvi
B28: 100/11861-403 Szekszárd | C28: 109/11715-1069 Dunaföldvár 10 | D28: 109/11715-1070 Paks 10 | E28: 109/11715-1051 Cece 12 | F28: 109/11715-1072 Paks 10
D29: 109/11715-1071 Paks 12 | F29: 109/11715-1073 Paks 12
D30: 109/11715-1074 Kulcs 11 | F30: 109/11715-986 Rácalmás 10
F31: 109/11715-1075 Alap 9
F32: 109/11715-1076 Sárbogárd
A34: Név
B35: 109/11715 Kitűzés 10 db | C35: 100/1600-3063 Dunaújváros | D35: 100/1601-1540 Siófok | E35: 100/1600-3049 Hantos | F35: 109/11715 Bemérés
C36: 100/1600-3057 Dunaújváros | E36: 100/1600-3064 Dunaújváros | F36: 109/11861-405 Szekszárd
A37: Suzuki | C37: 109/12120 Kulcs | E37: 109/11715-1080 Bonyhád
A38: NCH903 | C38: 100/1600-3056 Dújv | F38: RNB-601
C39: 100/166-3055 Dújv
A40: Név | B40: Galág-Pilisi | C40: Galág-Pilisi | D40: Galág-Pilisi | E40: Pilisi-Ritter | F40: Galág-Pilisi
C41: Scan | D41: Scan
A42: VW
A43: PUU152
A44: Név | B44: Jókai | C44: Jókai-Kulcsár | D44: Jókai-Kulcsár
A45: Szabadság | B45: Újváry | D45: Újváry | E45: Galág Újváry
A46: Beteg
A47: Távollét
A48: Magyarázat: | B48: Munkanapló hiányzik!!! | H48: Összesen : | I48: =SUM(I2:I47) -> 1

Sheet 06.24-06.30
A1: 26. hét | B1: hétfő 06.24 | C1: kedd 06.25 | D1: szerda 06.26 | E1: csütörtök 06.27 | F1: péntek 06.28 | G1: szombat 06.29 | H1: vasárnap 06.30 | I1: júniusban
B2: 100/1608-716 Szekszárd | C2: 100/1662-1 Paks | D2: 100/1601-1545 Siófok | E2: 100/1652-1548 Ságvár | F2: 100/1652-1549 Siófok
B3: 100/1600-3067 Bátaszék | C3: 100/1659-3072 dunaföldvár | E3: 100/1652-1541 Siófok | F3: 100/1600-2981 Dunaföldvár
A4: Ford | B4: 100/1662-2 Szekszárd | C4: 100/1652-1542 Tamási | F4: 100/1659-3077 Dunaföldvár
F5: 100/1600-2965 Dunaújváros
F6: 100/1600-2994 Rácalmás
F7: 100/1659-3076 Dunaújváros
A8: NGM157 | F8: 100/1600-3005 Adony
E9: Clió-601 | F9: Clió-601
A10: Név | B10: Balogh-Újváry | C10: Balogh-Újváry | D10: Balogh-Újváry | E10: Balogh-Újváry | F10: Balogh-Újváry | I10: =+'06.17-06.23'!I7 -> 1
B11: 100/1601-1543 Szántód | C11: Pa Rt | D11: 100/1601-1543 Szántód | E11: 100/1659-3071 Bonyhád | F11: Szekszárd Sportcsarnok szkennelése
A14: Név | B14: Jókai-Klieber | C14: Jókai | D14: Jókai-Klieber-Pilisi | E14: Jókai-Klieber | F14: Jókai-Klieber
B15: 100/1601-1539 Ádánd | C15: 100/1600-3068 Alsószentiván | D15: 100/1659-3064 Dunaújváros | E15: 100/1662-3 Dunaújváros | F15: 100/1659-3075 Sárbogárd
B16: 100/1608-710 Sióagárd | C16: 100/1608-697-701 Dunaújváros | D16: 109/12102 Dunakömlöd | E16: 100/1662-4 Dunaújváros | F16: 109/12108 Sárbogárd
A17: Clió | C17: 100/1608-707 Dunaújváros | D17: 100/1600-3049 Hantos | E17: 1113/10065 Paks 8:00 | F17: 100/1600-3024 Kulcs
A18: 602 | E18: 113/10065 Dunaújváros | F18: 100/1600-3049 Hantos
E19: 100/1659-3083 Kulcs
A20: Név | B20: Erős-Kunfalvi | C20: Erős-Kunfalvi | D20: Erős-Kunfalvi | E20: Erős-Kunfalvi | F20: Erős-Kunfalvi
C21: 100/1659-3062 Kulcs
A23: Clió
A24: 601
C27: Pilisi-Klieber
B28: 109/11715-978 Dunaföldvár 10 | C28: 109/11715-1078 Hidas 9 | D28: 109/11861-407 Szekszárd 8 | E28: 109/11715-1082 Nagyvenyim 12 | F28: 109/11715-1053 Dfvár 9
B29: 109/11715-1081 Paks 9 | C29: 109/11715-1079 Szakadát 11 | D29: 109/11715-1085 Gerjen 11 | E29: 109/11715-1083 Szakály 9 | F29: 109/11715-1084 Dfvár 12
B30: 109/11861-406 Szekszárd 8 | C30: 109/11715-1057 Madocsa 13 | D30: 109/11715-1077 Dunaszekcső | E30: 109/11715-1086 Szálka 9
E31: 109/11715-1061 Dunaújváros 12
A34: Név
B35: 109/11715 SMHV kitűzés | C35: 100/1659-3069 Szd | D35: 109/11715 SMHV Bemérés | E35: 109/11715 SMHV Bemérés | F35: 109/11715 SMHV kitűzés
C36: 100/1659-3073 Szd | D36: 109/12091 SMHV bemérés | E36: 109/12091 SMHV bemérés
A37: Suzuki | C37: 109/11715 SMHV kitűzés | D37: 109/11861 Köz bemérés | E37: 109/11861 Köz bemérés
A38: NCH903
E39: LSX-504 | F39: LSX-504
A40: Név | B40: Galág-Galág-Pilisi | C40: Galág-Galág | D40: Galág-Galág | E40: Galág-Galág-Pilisi | F40: Galág-Galág-Pilisi
A42: VW
A43: PUU152
A44: Név
A45: Szabadság | B45: Zsuzsa, Baka | C45: Zsuzsa | D45: Zsuzsa | E45: Zsuzsa | F45: Zsuzsa
A46: Beteg
A47: Távollét
A49: Magyarázat: | B49: Munkanapló hiányzik!!! | H49: Összesen : | I49: =SUM(I3:I48) -> 1

Sheet 07.01-07.07
A1: 27. hét | B1: hétfő 07.01 | C1: kedd 07.02 | D1: szerda 07.03 | E1: csütörtök 07.04 | F1: péntek 07.05 | G1: szombat 07.06 | H1: vasárnap 07.07 | I1: július
A3: Ford
A4: NGM157
A6: Név | B6: Balogh-
B7: Szekszárd Sportcsarnok szken | C7: PSE pálya kitűzés | D7: 10/1600-2997 Cikó 8 órára | F7: 100/1601-1472 Köröshegy
D8: 100/1659-3086 Kismányok
A9: NGM158 | D9: 100/1959-3082 Paks
A11: Név | B11: Jókai-Klieber-Pilisi | C11: Jókai-Klieber | D11: Balogh-Újváry-Klieber | E11: --------- | F11: Pilisi-Klieber | I11: 2
B12: 100/1659-3080 Dunaújváros 9 | C12: 113/10067 Dunaújváros | D12: 113/10066 Székesfehérvár | E12: 113/10066 Székesfehérvár | F12: 100/1661 Dujv
C13: 100/1608-708 Fácánkert | F13: 100/1600 Dujv környéke
A14: Clió
A15: RNB602
A17: Név | B17: Erős-Kunfalvi | C17: Erős-Pilisi | D17: Erős-Pilisi | E17: Erős-Pilisi | F17: Erős-Kunfalvi
B18: 100/1600-3075 Sárbogárd | C18: 109/12123 Mezőfalva 1/2 9 | E18: Pécs | F18: 100/1659-3078 Bölcske
B19: 109/12108 Sárbogárd | C19: 109/12124 Simontornya | F19: 109/12125 Paks 8-12/9
A20: Clió | C20: 100/1659-1545 Siófok | F20: 100/1659-3087 Baracs ?
A21: RNB601
A24: Név | B24: Balogh-Újváry | C24: Balogh-Újváry | D24: ----- | E24: Balogh-Újváry | F24: Balogh-Újváry
B25: 109/11715 SMHV Bemérés | C25: 109/11715 SMHV Bemérés | D25: 109/11715 SMHV | E25: 100/1652-1550 Iregszemcse | F25: 109/11715 SMHV kitűzés
B26: 109/11861 Köz Bemérés | C26: 109/11861 Köz Bemérés | D26: 109/12091 SMHV
A27: Dacia | B27: 109/12091 SMHV Bemérés | C27: 109/12091 SMHV Bemérés | E27: 109/12091 SMHV
A28: LSX504
A30: Név | B30: Galág-Galág | C30: Galág-Kunfalvi-Galág | D30: Galág-Galág-Kunfalvi | E30: Galág-Galág-Klieber | F30: Galág-Galág | I30: 1
B31: 109/11715-1087 Medina 11 | C31: 109/11715-1069 Dfvár 10 | D31: 109/11715-1094 Baracs 9 | E31: 109/11715-1089 Paks 10 | F31: 109/11715-1090 Paks 10
B32: 109/11715-1088 Tolna 12 | C32: 109/11715-1092 Perkáta 13 | D32: 109/11715-1095 Kisapostag 10 | E32: 109/11715-1097 Pszabolcs 10 | F32: 109/11715-1091 Paks 12
A33: tervezett | C33: 109/11715-1093 Dújváros 11 | E33: 109/11715-1098 Pszbolcs 13 | F33: 109/11715-1096 Kulcs 13
E34: 109/11715-1099 Pszabolcs 11 | F34: 109-11715--1100 Sárszágota 13
E35: 109/11715-1100 Sársztágota 13
A36: Név
A37: Suzuki
A38: NCH903
A40: Név
A41: VW
A42: PUU152
A43: Név
A44: Szabadság | D44: Jókai | E44: Jókai | F44: Jókai
A45: Beteg
A46: Távollét
A48: Magyarázat: | B48: Munkanapló hiányzik!!! | H48: Összesen : | I48: =SUM(I2:I47) -> 3

Sheet 07.08-07.14
A1: 28. hét | B1: hétfő 07.08 | C1: kedd 07.09 | D1: szerda 07.10 | E1: csütörtök 07.11 | F1: péntek 07.12 | G1: szombat 07.13 | H1: vasárnap 07.14
A3: Ford
A4: NGM157
A6: Név
B7: 100/1652-1551 Tab | C7: 100/1659-3089 Véménd | D7: 100/1659-3088 Dunaújváros | E7: 100/1659-3088 Dunaújváros | F7: 100/1659-3092 Sárkeresztúr
C8: 100/1659-3090 Véménd | D8: 110/10087 Paks PSE 8
A9: Ford
A10: NGM158
A12: Név | B12: Jókai-Klieber | C12: Jókai-Klieber | D12: Jókai-Klieber | E12: Jókai-Klieber-Balogh | F12: Jókai-Klieber | I12: =+'07.01-07.07'!I11+4 -> 6
B13: 100/1659-3081 Tolna | C13: 100/1608-512 Döbrököz | D13: 109/11715-1111 Bonyhád 8 | E13: 100/1659-3085 Rácalmás | F13: 113/10068 TECHNO utólagos
C14: 100/1600-3039 Sárosd | D14: 100/1600-3044 Fácánkert | E14: 109/12126 Paks | F14: 15+1 db kitűzés
A15: Clió | D15: 109/11861-403 Szekszárd
A16: 602
A18: Név | B18: Erős | C18: Erős-Galág2 | D18: Erős-Galág2-Galág | E18: Erős-Galág2 | F18: Erős-Galág2
B19: 100/1659-3057 Dunaújváros | C19: 100/1659-3074 Dunaújváros | D19: 100/1659-3088 Dunaújváros | F19: 100/1601-1492 Andocs
B20: 100/1659-3074 Dunaújváros | C20: 100/1659-3085 Rácalmás | F20: 100/1601-1522 Nagyszokoly
A21: Clió | F21: 100/1601-1531 Koppányszántó
A22: 601
A24: Név | B24: Balogh-Újváry | C24: Balogh-Újváry | D24: Balogh-Újváry | F24: Balogh-Újváry | I24: 1
C25: 109/11715-1101 Paks 10 | E25: 109/11861-407 Szekszárd 8 | F25: 109/11715-1102 Zomba 12
C26: 109/11715-1103 Mohács 9 | D26: 109/11715-1085 Gerjen 13 | E26: 109/11715-1057 Madocsa 9 | F26: 109/11715-1109 Felsőnána 13
C27: 109/11861-408 Paks 9 | F27: 109/11715-1073 Paks 13
B30: 109/11715 SMHV kitűzés | C30: 109/11715 SMHV bemérés | E30: 109/11715 SMHV bemérés | F30: 109/11715 SMHV kitűzés
B31: 109/12091 SMHV bemérés | C31: 109/12091 SMHV bemérés | E31: 109/12091 SMHV bemérés
A32: Dacia | C32: 109/12109 Paks 10
A33: LSX-504 | C33: 109/11861 Paks 9
A35: Név | B35: Galág-Galág | C35: Galág-Galág | E35: Galág-Galág | F35: Galág-Galág
A37: Suzuki
A38: NCH903
A39: Név
A40: VW
A41: PUU152
A42: Név
A43: Szabadság | B43: Kunfalvi | C43: Kunfalvi | D43: Kunfalvi, Galág | E43: Kunfalvi, Újváry | F43: Zsuzsa, Kunfalvi, Erika
A44: Beteg | B44: Pilisi | C44: Pilisi | D44: Pilisi | E44: Pilisi | F44: Pilisi
A45: Távollét
A47: Magyarázat: | B47: Munkanapló hiányzik!!! | H47: Összesen : | I47: =SUM(I1:I46) -> 7

Sheet 07.15-07.21
A1: 29. hét | B1: hétfő 07.15 | C1: kedd 07.16 | D1: szerda 07.17 | E1: csütörtök 07.18 | F1: péntek 07.19 | G1: szombat 07.20 | H1: vasárnap 07.21
B2: 100/1662-6 Zomba gázvez kitűzés | C2: 100/1659-3088 Dunaújváros
B3: terepjáró kell | C3: 100/1658 léges
A4: Ford | B4: 100/1658 léges
A5: NGM157
B6: Mazda | C6: Mazda
A7: Név | B7: Balogh-Pilisi-Újváry | C7: Balogh-Pilisi-Újváry | I7: =+'07.08-07.14'!I24+2 -> 3
B8: 110/10087 Paks PSE | C8: 100/1608-512 de. Döbrököz | D8: 109/12127 Pusztaszabolcs | E8: 100/1652-1552 Tab 10
E9: 100/1658 léges
A10: Ford | E10: 100/1652-1548 Ságvár
A11: NGM158
A14: Név | B14: Jókai-Klieber | C14: Jókai-Klieber | D14: Jókai-Klieber-Pilisi | E14: Jókai-Klieber-Pilisi | I14: =+'07.08-07.14'!I12+4 -> 10
B15: 100/1600-3061 Szekszárd 13 óra | C15: 110/10119 Szálka 1/2 9 | D15: 113/10069 Dunaszentgyörgy | E15: 100/1600-3061 Szd 14 | F15: 100/1659-3094 Paks
B16: 100/1662-005 Rácalmás tervezési | D16: 100/1662-7 Rácalmás | E16: 100/1600-3044 Fácánkert
A17: Clió | D17: 113/10068 Dunaújváros | E17: 100/1658 léges
A18: 602
A20: Név | B20: Erős-Kunfalvi | C20: Erős-Kunfalvi | D20: Erős-Kunfalvi | E20: Erős-Kunfalvi | F20: Erős-Kunfalvi-Pilisi
D21: 109/12091-6 SMHV
A23: Clió
A24: 601
A27: Név | D27: Balogh-Újváry
B28: 109/11715-1061 Dújváros 10 | C28: 109/11715-1105 Adony 10 | D28: 109/11715-1070 Paks 9 | E28: 109/11715-1107 Sbogárd 9 | F28: 109/11715-1108 Rácalmás 10
B29: 109/11715-1104 Kulcs 14 | C29: 109/11715-1106 Iváncsa 13 | D29: 109/11715-1110 Paks 12 | E29: 109/11861-412 Bátaszék 10 | F29: 109/11715-1079 Szakadát 9
C30: 109/11861-409 Szekszárd 8 | D30: 109/11861-410 Szekszárd 8 | F30: 109/11715-1051 Cece 12
D31: 109/11861-411 Tolna 12 | F31: 109/11861-413 Bátaszék 8
F32: 109/11861-414 Bátaszék
F33: 109/11861-415 Bátaszék 10
F34: 109/11861-416 Bátaszék 11
A35: Név
B36: 109/11715 SMHV kitűzés | C36: 109/11715 SMHV bemérés | D36: 109/11715 SMHV bemérés | E36: 109/11715 SMHV bemérés | F36: 109/11715 SMHV kitűzés
A37: Dacia | C37: 109/11861 Köz-Meg bemérés | D37: 109/11861 Köz-Meg bemérés | E37: 109/11861 Köz-Meg bemérés
A38: LSX504 | D38: 100/1600-3061 Szekszárd kutat
A41: Név | B41: Galág-Galág-Galág | C41: Galág-Galág-Galág | D41: Galág-Galág-Galág | E41: Galág-Galág | F41: Galág-Galág
A42: Suzuki | E42: 109/12091-6 SMHV | F42: 109/12091-6 SMHV
A43: NCH903 | E43: 100/1659-3088 Dunaújváros ? | F43: 100/1659-3088 Dunaújváros ?
A45: Név | E45: Balogh-Újváry-Galág | F45: Balogh-Újváry-Galág
A46: Szabadság | B46: Zsuzsa, Erika, Sanyi | C46: Zsuzsa | D46: Zsuzsa | E46: Zsuzsa | F46: Zsuzsa, Klieber, Jókai
A47: Beteg
A48: Távollét
A50: Magyarázat: | B50: Munkanapló hiányzik!!! | H50: Összesen : | I50: =SUM(I4:I49) -> 13

Sheet 07.22-07.28
A1: 30. hét | B1: hétfő 07.22 | C1: kedd 07.23 | D1: szerda 07.24 | E1: csütörtök 07.25 | F1: péntek 07.26 | G1: szombat 07.27 | H1: vasárnap 07.28
C2: Székesfehérvár alkatrész | F2: 100/1652-1555 Siófok
B3: 8 Szerviz Kürtősy | F3: 100/1652-1554 Siófok
A4: Ford
A5: NGM157
A7: Név | B7: Kunfalvi | C7: Kunfalvi | F7: Balogh-Újváry-Pilisi
B8: 100/1659-3095 Györköny | C8: 110/10087 Paks PSE | D8: 100/1600-2997 Cikó 13 | E8: 100/1652-1553 Siójut 10
C9: 100/1659-3095 Györköny | D9: 113/10062 Paks 8 Kitűzés | E9: Siófoki Fh>Eon lead
A10: Ford
A11: NGM158
A14: Név | B14: Jókai-Pilisi | C14: Jókai-Pilisi | D14: Jókai-Pilisi | E14: Jókai-Pilisi | I14: =+'07.15-07.21'!I14+4 -> 14
B15: 100/1659-3089 Véménd | C15: 100/1600-3061 Szekszárd 13 | D15: 100/1662-11 Pincehely 8óra Kitűz | E15: 100/1662-14 Szekszárd | F15: 113/10068 TECHNO utólagos9db
B16: 100/1659-3090 Véménd | C16: 100/1662-10 Szekszárd 8:00 | D16: 100/1659-3098 Simontornya | E16: 100/1662-11 Pincehely 13
A17: Clió | B17: 100/1659-3096 Mohács | E17: 100/1662-13 Tolna
A18: 602
A20: Név | B20: Erős-Galág2-Kunfalvi | C20: Erős-Galág2 | D20: Erős-Kunfalvi | E20: Erős-Galág2 | F20: Erős-Kunfalvi
B21: 100/1659-3088 Dunaújváros | C21: 100/1600-2984 Paks | D21: 100/1659-3088 Dunaújváros | E21: 100/1659-3100 Bonyhád
C22: 100/1600-3013 Tolna | D22: 100/1662-12 Dunaújváros bemér
A23: Clió | C23: 109/11861-417 Szd | D23: 109/12126 Paks
A24: 601
A27: Név | B27: Balogh-Újváry | C27: Balogh-újváry | D27: Balogh-Újváry | E27: Balogh-Újváry | I27: =+'07.15-07.21'!I7+1 -> 4
B28: 109/11715-1085 Gerjen 9 | C28: 109/11715-1112 Tolna 9 | D28: 109/12108 Sárbogárd | E28: 109/12091-6 SMHV bemér | F28: 109/11715-1113 Alsónyék 9
B29: 109/11715-1114 Nagymányok 12 | C29: 109/11861-417 Szekszárd | D29: 100/1600-3043 Kajdacs | E29: 109/11861 Köz bemér
A30: Dacia | B30: 100/1600-3014 Szd 14 | D30: 100/1659-3065 Kajdacs | E30: 109/12106 Paks bemér 8
A31: Lsx-504 | B31: 109/11861 Köz bemér | C31: 109/12091-6 SMHV bemér | D31: 109/12091-6 SMHV bemér | E31: 100/1661-1-4 Bátaszék | F31: 100/11715 SMHV kitűzés
B32: 109/12091-6 SMHV bemér | C32: 109/11861 Köz bemér | D32: 109/11861 Köz bemér
A34: Név | B34: Galág-Galág | C34: Galág-Galág | D34: Galág-Galág | E34: Galág-Galág | F34: Galág-Galág-Galág
A37: Suzuki
A38: NCH903
A40: Név
A42: VW
A43: PUU152
A44: Név
A45: Szabadság | B45: Klieber | C45: Klieber | D45: Klieber | E45: Klieber, Kunfalvi | F45: Klieber, Jókai
A46: Beteg
A47: Távollét
A49: Magyarázat: | B49: Munkanapló hiányzik!!! | H49: Összesen : | I49: =SUM(I3:I48) -> 18

Sheet 07.29-08.04
A1: 31. hét | B1: hétfő 07.29 | C1: kedd 07.30 | D1: szerda 07.31 | E1: csütörtök 08.01 | F1: péntek 08.02 | G1: szombat 08.03 | H1: vasárnap 08.04
B2: 100/1659-3088 Dunaújváros | C2: 100/1659-3094 Zomba | D2: 111/10008 | E2: 100/1600-3059 Dunaszekcső | F2: 100/1659-3103 Paks
B3: 109/12108 Sárbogárd | C3: 109/12129 Simontornya | D3: Szalkszentmárton kavicsbánya | E3: 100/1662-15 Kakasd 12 után | F3: 113/10071 utólagos
A4: Ford | E4: 113/10071 utólagos
A5: NGM157 | C5: 109/12130 Szedres 8
A7: Név | B7: Balogh-Újváry-Pilisi | C7: Pilisi-Klieber | D7: Kulcsár Pilisi | E7: Pilisi-Jókai | F7: Erős-Kunfalvi | I7: 1
B8: 110/10087 Paks PSE | C8: 100/ ? PA Rt | D8: 100/ ? PA Rt | F8: 113/10071 utólagos
B9: 100/1659-3099 Adony
A10: Ford
A11: NGM158
A14: Név | B14: Jókai-Klieber | C14: Jókai | D14: Jókai | F14: Jókai-Klieber | I14: =+'07.22-07.28'!I14+3 -> 17
C15: Pécs | D15: pécs | E15: pécs | F15: 113/10071 utólagos
F16: 109/12132 Szekszárd
A17: Clió
A18: 601
A20: Név | C20: Balogh-Újváry | D20: Balogh-Újváry | E20: Balogh-Újváry | F20: Balogh-Újváry
C21: 109/12109 Paks 11 | D21: 113/10070 Bonyhád 8:00 | E21: 100/1659-3105 Paks
D22: 100/1662-16 Nagyszokoly 11:00 | E22: PAVILL leadás
A23: Clió | D23: 113/10068 Gerjen | E23: 100/1659-3103 Paks
A24: 602 | E24: 109/12128 Paks
A27: Név | B27: Erős-Kunfalvi | C27: Erős-Kunfalvi | D27: Erős-Kunfalvi | E27: Erős-Kunfalvi
B28: 109/11715-1115 Nagykarácsony 13.30 | C28: 109/11715-1078 Hidas 9 | D28: 109/11715-1102 Zomba 9
C29: 109/11715-1116 Bonyhád 11,30 | D29: 109/11715-1117 Györköny 11,30 | E29: 109/11715-1106 Iváncs 10
A30: Dacia | C30: 109/11715-1119 Simontornya 10 | D30: 109/11715-1120 Besnyő 12 | E30: 109/11715-1118 Besnyő 12
A31: Lsx-504 | B31: 100/11715 SMHV kitűzés | D31: 109/11715-1061 Dunaújváros | E31: 109-11715-1057 Madocsa12
B32: 100/11715 SMHV bemérés | E32: 109/11861-418 Szekszárd 8 | F32: 100/11715 SMHV kitűzés
B33: 109/12091-6 SMHV bemérés | D33: 109/11861-418 Szekszárd 8
A34: Név | B34: Galág-Galág2 | C34: Galág-Galág | D34: Galág-Klieber | E34: Galág-Klieber | F34: Galág-Pilisi
A37: Suzuki
A38: NCH903
A40: Név
A42: VW
A43: PUU152
A44: Név
A45: Szabadság
A46: Beteg
A47: Távollét
H48: Összesen : | I48: =SUM(I2:I47) -> 18
A49: Magyarázat: | B49: Munkanapló hiányzik!!!

Sheet 08.05-08.11
A1: 32. hét | B1: hétfő 08.05 | C1: kedd 08.06 | D1: szerda 08.07 | E1: csütörtök 08.08 | F1: péntek 08.09 | G1: szombat 08.10 | H1: vasárnap 08.11
A3: Ford
A4: NGM157
A6: Név
B7: 100/1659-3104 Kajdacs 8-12 | C7: 100/1659-3101 Dunaújváros | D7: Szekszárd Nefelejcs köz 8:00 | E7: 100/1608-709 Hőgyész | G7: 100/1661-2 Bonyhád
C8: 100/1652-1556 Siófok | D8: 100/1659-3102 Bátaszék | E8: 100/1652-1556 Siófok Módosított 9:00 | G8: 100/1662-19 Pálfa
A9: Ford | E9: 100/1601-1482 Tamási | G9: 100/1658 léges csati
A10: NGM158 | E10: 100/1662-16 Nagyszokoly
A12: Név | B12: Jókai-Klieber | C12: Jókai-Klieber | D12: Jókai-Klieber | E12: Jókai-Klieber | G12: Jókai-Klieber | I12: =1+5 -> 6
C13: 109/11715-1121 Paks 9:30 | D13: 109/11715-1124 Kulcs13 | E13: 109/11715-1107 Sárbogárd 9 | F13: 109/11715-ös kitűzések | G13: 100/1658 léges csati
D14: 109/11715-1051 Cece 11:30 | E14: 109/11715-1123 Nagyszékely13 | G14: Szd-Paks-Sárbogárd
A15: Dacia | E15: 109/11715-1125 Bonyhád 10
A16: LSX504 | B16: 109/11715 SMHV kitűz-bemér
A18: Név | B18: Galág-Pilisi | C18: Galág-Pilisi | D18: Galág-Kunfalvi | E18: Galág-Pilisi | F18: Pilisi-Klieber | G18: Pilisi
B19: 113/10071 Madocsa 8:30 | C19: 100/1638 Magyarszék | D19: 109/11861-420 Szd. | E19: 1662-17-Kulcs Gfk bem. 12:30 | F19: 100/1659-3109 Szekszárd
B20: 100/1662-007 Rácalmás bemérés | D20: 109/11861-421 Szd. | E20: 100/1662-18 Decs | F20: 100/1600-3008 Nagydorog
A21: Clió | B21: 100/1659-3106 Hőgyész kitűzés | E21: 100/1658 léges csati
A22: 601
A25: Név | B25: Balogh-Újváry | C25: Balogh-Újváry | D25: Balogh-Újváry | E25: Balogh-Újváry | F25: Balogh-Újváry | I25: 1
B26: 100/1659-3107 Somberek terv | C26: 100/1659-3097 Zomba | D26: 113/10066 Székesfehérvár | E26: 109/12131 Szekszárd 8:00 | F26: 113/10071 utólagos | G26: 100/1658 léges csati
C27: 100/1659-3100 Bonyhád 8.30 | E27: Erős utána szerk | F27: 100/1658 léges csati | G27: Bonyhád-Bátaszék-Mohács
A28: Clió | E28: 100/1659- Kisvejke 13.00 | F28: Kurd-Lengyel -Tevel
A29: 602
A32: Név | B32: Erős-Kunfalvi | C32: Erős-Kunfalvi | D32: Erős-Pilisi | E32: Erős-Kunfalvi | F32: Erős-Kunfalvi | G32: Erős-Kunfalvi
A35: Suzuki
A36: NCH903
A38: Név
A40: VW
A41: PUU152
A42: Név
A43: Szabadság | F43: Jókai | G43: Galág
A44: Beteg | F44: Galág | G44: Balogh
A45: Távollét | G45: Újváry
A46: Magyarázat: | B46: Munkanapló hiányzik!!! | H46: Összesen : | I46: =SUM(I2:I45) -> 7

Sheet 08.12-08.18
A1: 33. hét | B1: hétfő 08.12 | C1: kedd 08.13 | D1: szerda 08.14 | E1: csütörtök 08.15 | F1: péntek 08.16 | G1: szombat 08.17 | H1: vasárnap 08.18
A4: Ford
A5: NGM157
A7: Név
B8: 100/1652-1557 Zamárdi 9 óra | C8: Pécs scen | D8: 100/1659-3110 Sáregres | E8: PSE pálya | F8: 100/1652-1660 Szántód
B9: 100/1652-1558 B.őszöd 13óra | D9: 109/12133 Szekszárd | F9: 100/1652-1559 Siófok
A10: Ford
A11: NGM158
A14: Név | B14: Jókai-Pilisi | C14: Jókai-Pilisi | D14: Jókai-Pilisi | E14: Jókai-Pilisi | F14: Jókai-Pilisi | I14: =+'08.05-08.11'!I12+1 -> 7
B15: 109/11715-1130 Madocsa 10 | C15: 109/12091 SMHV | D15: 109/11715-1127 Bölcske 9 | E15: 109/11715-1126 Paks Ip.Park
B16: 109/11715-1129 Madocsa 9 | C16: 100/1658-2 Eon lég | D16: 109/11715-1128 Györköny 14 | E16: 100/1662-19 Pálfa
A17: Dacia | B17: 100/1658-2 Eon lég | D17: 109/11715-1131 Rácalmás 13
A18: LSX504 | D18: 109/11715-1061 Dújváros 10
A20: Név | B20: Galág-Kunfalvi | C20: Galág-Kunfalvi | D20: Galág-Kunfalvi | E20: Galág-Kunfalvi
B21: 100/1600-3026 Várdomb | F21: 109/11715 SMHV kitűz
B22: 100/1658-2 Eon lég
A23: Clió
A24: 601
A27: Név | B27: Balogh- | F27: Galág-Kunfalvi | I27: =+'08.05-08.11'!I25 -> 1
C28: 100/1659-3113 Paks | D28: 109/11861-422 Szekszárd | E28: 113/10073 Baracs 9:00 | F28: 100/1659-3114 Dunaújváros
C29: 100/1658-2 Eon lég | D29: 100/1662-20 Tolna | E29: 100/1658-2 Eon lég
A30: Clió | C30: 100/1659-3061 Szd 13 | D30: 100/1662-10 Szekszárd
A31: 602 | D31: 100/1662-15 Kakasd
D32: 100/1600-3013 Tolna
A34: Név | C34: Erős-Balogh | D34: Erős-Ujváry | E34: Erős-Ujváry | F34: Erős-Ujváry
B35: 100/1643 Edelény | C35: 100/1643 Edelény | D35: 100/1643 Edelény | E35: 100/1643 Edelény | F35: 100/1643 Edelény
A37: Suzuki
A38: NCH903
A40: Név | B40: Iván Zs. | C40: Iván Zs. | D40: Iván Zs. | E40: Iván Zs. | F40: Iván Zs.
A42: VW
A43: PUU152
A44: Név
A45: Szabadság | B45: Újváry | C45: Újváry | D45: Balogh | E45: Balogh | F45: Balogh
A46: Beteg | B46: Klieber | C46: Klieber | D46: Klieber | E46: Klieber | F46: Klieber
A47: Távollét
A48: Magyarázat: | B48: Munkanapló hiányzik!!! | H48: Összesen : | I48: =SUM(I4:I47) -> 8

Sheet 08.19-08.25
A1: 34. hét | B1: hétfő 08.19 | C1: kedd 08.20 | D1: szerda 08.21 | E1: csütörtök 08.22 | F1: péntek 08.23 | G1: szombat 08.24 | H1: vasárnap 08.25
A4: Ford
A5: NGM157 | D5: bármi
A7: Név
A10: Ford
A11: NGM158
A14: Név
D15: 109/11715-1133 Baracs 11 | E15: 109/11715-1134 Besnyő 10 | F15: 109/11715-1136 Mecseknádasd 12
D16: 109/11715-1129 Madocsa 13 | E16: 109/11715-1135 Dunaföldvár 12
A17: Dacia
A18: LSX504
A20: Név
A23: Dacia
A24: LTZ294
A27: Név
A30: Mazda
A31: JZA908
A34: Név
A37: Suzuki
A38: NCH903
A40: Név
... A44: Név
A45: Szabadság | D45: Galág | E45: Galág | F45: Pilisi Galág
A46: Beteg

Sheet 08.26-09.01
A1: 23. hét | B1: hétfő 06.03 | C1: kedd 06.04 | D1: szerda 06.05 | E1: csütörtök 06.06 | F1: péntek 06.07 | G1: szombat 06.08 | H1: vasárnap 06.09
B2: 100/1600-3048 Dunaújváris | C2: 109/11715-1062 Ófalu 9 | D2: 109/11715-1009 Bonyhád 9 | E2: 109/11715-892 Mohács 9 | F2: 109/11715-1052 Rácalmás 10
C3: 109/11715-1063 Ófalu 10 | D3: 100/1608-710 Sióagárd | E3: 100/1600-3050 Véménd | F3: 109/11715-1061 Dunaújváros 12
A4: Ford | C4: 109/11861- Szd 3db | D4: 109/11861- Szd | F4: 109/11715-1064 Rácalmás 13
A5: NGM157 | D5: 109/11861-402 Dombori | F5: 109/11715-1060 Dunaföldvár 10
D6: Orvosi 7:45
A7: Név | B7: Balogh-Tolnai | C7: Balogh-Tolnai | D7: Balogh | E7: Balogh-Tolnai | F7: Balogh-Tolnai
B8: 100/1608-705 Szekszárd du. | C8: 100/1608-711 Dunaföldvár | D8: 109/11715-1051 Cece 10 | E8: 100/1600-3051 Cece
B9: 100/1600-3052 Sárhatvan | C9: 109/12113 Dunaszentgyörgy | D9: 100/1600-3055 Dunaújváros | E9: 100/1608-706 Tamási
A10: Ford | B10: 100/1600-3054 Nagyvenyim | D10: 100/1600-3056 Dunaújváros | E10: 110/10087 Paks PSE 8
A11: NGM158 | B11: 100/1608-693 Szakály | C11: 113/ Zomba | D11: 100/1608-701 Dunaújváros 14:30
A14: Név | B14: Jókai Klieber | C14: Jókai Klieber | D14: Jókai Klieber | E14: Jókai Klieber
B15: 100/1600-3048 Dunaújváros | C15: 100/1600-3053 Dunaújváros 8:30 | D15: 109/11715-1057 Madocsa 11 | E15: 109/11715-1059 Nagyvenyim 10 | F15: Scen
B16: 109/11715-1053 Dunaföldvár 9 | C16: 109/11715-1054 Rácalmás 10 | D16: 109/11715-1058 Madocsa 12 | E16: 109/11715-1056 Sárosd 10
B17: 100/1608-707 Dunaújváros 14:00 | C17: 109/12106 Paks Völgy | D17: 100/1599 Eon léges | E17: 100/1599 Eon léges
A18: Dacia | B18: 109/11715-1065 Dunaföldvár 11 | C18: 109/12091-4 SMHV | D18: 100-11861-400 Szálka 12 | E18: 100/1608-701 Dunaújváros 8:30
A19: LSX504 | B19: 109/12109 Paks | D19: 100/1600-3053 Dunaújváros
D20: Orvosi 7:45
A21: Név | B21: Erős-Kunfalvi | C21: Erős-Kunfalvi | D21: Erős-Kunfalvi | E21: Erős-Kunfalvi | F21: Jókai Klieber
A22: Dacia
A23: LTZ294
A25: Név
D26: 100/1600-3035 Szabadegyháza | E26: 100/1600-3035 Szabadegyháza | F26: 100/1600-3035 Szabadegyháza
A28: Mazda
A29: JZA908
A31: Név | D31: Galág-Pilisi | E31: Galág-Pilisi | F31: Galág-Pilisi
B32: 100/1600-3035 Szabadegyháza | C32: 100/1600-3035 Szabadegyháza | F32: 113/10060 utólagos 6db
F33: 109/11861-401 Gyönk 8
F34: 100/1608-714 Bonyhád
A35: Suzuki
A36: NCH903
A38: Név | B38: Galág-Pilisi | C38: Galág-Pilisi | F38: Erős-Kunfalvi
A40: VW
A41: PUU152
A42: Név
A43: Szabadság | D43: Tolnai
A44: Beteg
A45: Távollét
H46: Összesen :
A47: Magyarázat: | B47: Munkanapló hiányzik!!!

Sheet 09.02-09.08
A1: 30. hét | B1: hétfő 07.22 | C1: kedd 07.23 | D1: szerda 07.24 | E1: csütörtök 07.25 | F1: péntek 07.26 | G1: szombat 07.27 | H1: vasárnap 07.28
C2: Székesfehérvár alkatrész | F2: 100/1652-1555 Siófok
B3: 8 Szerviz Kürtősy | F3: 100/1652-1554 Siófok
A4: Ford
A5: NGM157
A7: Név | B7: Kunfalvi | C7: Kunfalvi | F7: Balogh-Újváry-Pilisi
B8: 100/1659-3095 Györköny | C8: 110/10087 Paks PSE | D8: 100/1600-2997 Cikó 13 | E8: 100/1652-1553 Siójut 10
C9: 100/1659-3095 Györköny | D9: 113/10062 Paks 8 Kitűzés | E9: Siófoki Fh>Eon lead
A10: Ford
A11: NGM158
A14: Név | B14: Jókai-Pilisi | C14: Jókai-Pilisi | D14: Jókai-Pilisi | E14: Jókai-Pilisi | I14: =+'07.15-07.21'!I14+4 -> 14
B15: 100/1659-3089 Véménd | C15: 100/1600-3061 Szekszárd 13 | D15: 100/1662-11 Pincehely 8óra Kitűz | E15: 100/1662-14 Szekszárd | F15: 113/10068 TECHNO utólagos9db
B16: 100/1659-3090 Véménd | C16: 100/1662-10 Szekszárd 8:00 | D16: 100/1659-3098 Simontornya | E16: 100/1662-11 Pincehely 13
A17: Clió | B17: 100/1659-3096 Mohács | E17: 100/1662-13 Tolna
A18: 602
A20: Név | B20: Erős-Galág2-Kunfalvi | C20: Erős-Galág2 | D20: Erős-Kunfalvi | E20: Erős-Galág2 | F20: Erős-Kunfalvi
B21: 100/1659-3088 Dunaújváros | C21: 100/1600-2984 Paks | D21: 100/1659-3088 Dunaújváros | E21: 100/1659-3100 Bonyhád
C22: 100/1600-3013 Tolna | D22: 100/1662-12 Dunaújváros bemér
A23: Clió | C23: 109/11861-417 Szd | D23: 109/12126 Paks
A24: 601
A27: Név | B27: Balogh-Újváry | C27: Balogh-újváry | D27: Balogh-Újváry | E27: Balogh-Újváry | I27: =+'07.15-07.21'!I7+1 -> 4
B28: 109/11715-1085 Gerjen 9 | C28: 109/11715-1112 Tolna 9 | D28: 109/12108 Sárbogárd | E28: 109/12091-6 SMHV bemér | F28: 109/11715-1113 Alsónyék 9
B29: 109/11715-1114 Nagymányok 12 | C29: 109/11861-417 Szekszárd | D29: 100/1600-3043 Kajdacs | E29: 109/11861 Köz bemér
A30: Dacia | B30: 100/1600-3014 Szd 14 | D30: 100/1659-3065 Kajdacs | E30: 109/12106 Paks bemér 8
A31: Lsx-504 | B31: 109/11861 Köz bemér | C31: 109/12091-6 SMHV bemér | D31: 109/12091-6 SMHV bemér | E31: 100/1661-1-4 Bátaszék | F31: 100/11715 SMHV kitűzés
B32: 109/12091-6 SMHV bemér | C32: 109/11861 Köz bemér | D32: 109/11861 Köz bemér
A34: Név | B34: Galág-Galág | C34: Galág-Galág | D34: Galág-Galág | E34: Galág-Galág | F34: Galág-Galág-Galág
A37: Suzuki
A38: NCH903
A40: Név
A42: VW
A43: PUU152
A44: Név
A45: Szabadság | B45: Klieber | C45: Klieber | D45: Klieber | E45: Klieber, Kunfalvi | F45: Klieber, Jókai
A46: Beteg
A47: Távollét
A49: Magyarázat: | B49: Munkanapló hiányzik!!! | H49: Összesen : | I49: =SUM(I3:I48) -> 18

Sheet 09.09-09.15
A1: 37. hét | B1: hétfő 09.09 | C1: kedd 09.10 | D1: szerda 09.11 | E1: csütörtök 09.12 | F1: péntek 09.13 | G1: szombat 09.14 | H1: vasárnap 09.15
A4: Ford
A5: NGM157
A7: Név
A10: Ford
A11: NGM158
A14: Név
A17: Dacia
A18: LSX504
A20: Név
A23: Dacia
A24: LTZ294
A27: Név
... A44: Név
A45: Szabadság | B45: Jókai
A46: Beteg

Sheet 09.16-09.22
A1: 38. hét | B1: hétfő 09.16 | C1: kedd 09.17 | D1: szerda 09.18 | E1: csütörtök 09.19 | F1: péntek 09.20 | G1: szombat 09.21 | H1: vasárnap 09.22
A4: Ford
A5: NGM157
A7: Név
A10: Ford
A11: NGM158
A14: Név
A17: Dacia
A18: LSX504
A20: Név
A23: Dacia
A24: LTZ294
A27: Név
... A46: Beteg

Sheet 09.23-09.29
A1: 39. hét | B1: hétfő 09.23 | C1: kedd 09.24 | D1: szerda 09.25 | E1: csütörtök 09.26 | F1: péntek 09.27 | G1: szombat 09.28 | H1: vasárnap 09.29
A4: Ford
A5: NGM157
A7: Név
A10: Ford
A11: NGM158
A14: Név
A17: Dacia
A18: LSX504
A20: Név
A23: Dacia
A24: LTZ294
A27: Név
... A46: Beteg

Sheet 09.30-10.06
A1: 40. hét | B1: hétfő 09.30 | C1: kedd 10.01 | D1: szerda 10.02 | E1: csütörtök 10.03 | F1: péntek 10.04 | G1: szombat 10.05 | H1: vasárnap 10.06
A4: Ford
A5: NGM157
A7: Név
A10: Ford
A11: NGM158
A14: Név
A17: Dacia
A18: LSX504
A20: Név
A23: Dacia
A24: LTZ294
A27: Név
... A46: Beteg

Sheet 10.07-10.13
A1: 41. hét | B1: hétfő 10.07 | C1: kedd 10.08 | D1: szerda 10.09 | E1: csütörtök 10.10 | F1: péntek 10.11 | G1: szombat 10.12 | H1: vasárnap 10.13
A4: Ford
A5: NGM157
A7: Név
A10: Ford
A11: NGM158
A14: Név
A17: Dacia
A18: LSX504
A20: Név
A23: Dacia
A24: LTZ294
A27: Név
... A46: Beteg

Sheet 10.14-10.20
A1: 42. hét | B1: hétfő 10.14 | C1: kedd 10.15 | D1: szerda 10.16 | E1: csütörtök 10.17 | F1: péntek 10.18 | G1: szombat 10.19 | H1: vasárnap 10.20
A4: Ford
A5: NGM157
A7: Név
A10: Ford
A11: NGM158
A14: Név
A17: Dacia
A18: LSX504
A20: Név
A23: Dacia
A24: LTZ294
A27: Név
... A46: Beteg

Sheet 10.21-10.27
A1: 43. hét | B1: hétfő 10.21 | C1: kedd 10.22 | D1: szerda 10.23 | E1: csütörtök 10.24 | F1: péntek 10.25 | G1: szombat 10.26 | H1: vasárnap 10.27
A4: Ford
A5: NGM157
A7: Név
A10: Ford
A11: NGM158
A14: Név
A17: Dacia
A18: LSX504
A20: Név
A23: Dacia
A24: LTZ294
A27: Név
... A46: Beteg

Sheet 10.28-11.03
A1: 44. hét | B1: hétfő 10.28 | C1: kedd 10.29 | D1: szerda 10.30 | E1: csütörtök 10.31 | F1: péntek 11.01 | G1: szombat 11.02 | H1: vasárnap 11.03
A4: Ford
A5: NGM157
A7: Név
A10: Ford
A11: NGM158
A14: Név
A17: Dacia
A18: LSX504
A20: Név
A23: Dacia
A24: LTZ294
A27: Név
... A46: Beteg

Sheet 11.04-11.10
A1: 45. hét | B1: hétfő 11.04 | C1: kedd 11.05 | D1: szerda 11.06 | E1: csütörtök 11.07 | F1: péntek 11.08 | G1: szombat 11.09 | H1: vasárnap 11.10
A4: Ford
A5: NGM157
A7: Név
A10: Ford
A11: NGM158
A14: Név
A17: Dacia
A18: LSX504
A20: Név
A23: Dacia
A24: LTZ294
A27: Név
... A46: Beteg

Sheet 11.11-11.17
A1: 46. hét | B1: hétfő 11.11 | C1: kedd 11.12 | D1: szerda 11.13 | E1: csütörtök 11.14 | F1: péntek 11.15 | G1: szombat 11.16 | H1: vasárnap 11.17
A4: Ford
A5: NGM157
A7: Név
A10: Ford
A11: NGM158
A14: Név
A17: Dacia
A18: LSX504
A20: Név
A23: Dacia
A24: LTZ294
A27: Név
... A46: Beteg

Sheet 11.18-11.24
A1: 47. hét | B1: hétfő 11.18 | C1: kedd 11.19 | D1: szerda 11.20 | E1: csütörtök 11.21 | F1: péntek 11.22 | G1: szombat 11.23 | H1: vasárnap 11.24
A4: Ford
A5: NGM157
A7: Név
A10: Ford
A11: NGM158
A14: Név
A17: Dacia
A18: LSX504
A20: Név
A23: Dacia
A24: LTZ294
A27: Név
... A46: Beteg

Sheet 11.25-12.01
A1: 48. hét | B1: hétfő 11.25 | C1: kedd 11.26 | D1: szerda 11.27 | E1: csütörtök 11.28 | F1: péntek 11.29 | G1: szombat 11.30 | H1: vasárnap 12.01
A4: Ford
A5: NGM157
A7: Név
A10: Ford
A11: NGM158
A14: Név
A17: Dacia
A18: LSX504
A20: Név
A23: Dacia
A24: LTZ294
A27: Név
... A46: Beteg

Sheet 12.02-12.08
A1: 49. hét | B1: hétfő 12.02 | C1: kedd 12.03 | D1: szerda 12.04 | E1: csütörtök 12.05 | F1: péntek 12.06 | G1: szombat 12.07 | H1: vasárnap 12.08
A4: Ford
A5: NGM157
A7: Név
A10: Ford
A11: NGM158
A14: Név
A17: Dacia
A18: LSX504
A20: Név
A23: Dacia
A24: LTZ294
A27: Név
... A46: Beteg

Sheet 12.09-12.15
A1: 50. hét | B1: hétfő 12.09 | C1: kedd 12.10 | D1: szerda 12.11 | E1: csütörtök 12.12 | F1: péntek 12.13 | G1: szombat 12.14 | H1: vasárnap 12.15
A4: Ford
A5: NGM157
A7: Név
A10: Ford
A11: NGM158
A14: Név
A17: Dacia
A18: LSX504
A20: Név
A23: Dacia
A24: LTZ294
A27: Név
... A46: Beteg

Sheet 12.16-12.22
A1: 51. hét | B1: hétfő 12.16 | C1: kedd 12.17 | D1: szerda 12.18 | E1: csütörtök 12.19 | F1: péntek 12.20 | G1: szombat 12.21 | H1: vasárnap 12.22
A4: Ford
A5: NGM157
A7: Név
A10: Ford
A11: NGM158
A14: Név
A17: Dacia
A18: LSX504
A20: Név
A23: Dacia
A24: LTZ294
A27: Név
... A46: Beteg

Sheet 12.23-12.29
A1: 52. hét | B1: hétfő 12.23 | C1: kedd 12.24 | D1: szerda 12.25 | E1: csütörtök 12.26 | F1: péntek 12.27 | G1: szombat 12.28 | H1: vasárnap 12.29
A4: Ford
A5: NGM157
A7: Név
A10: Ford
A11: NGM158
A14: Név
A17: Dacia
A18: LSX504
A20: Név
A23: Dacia
A24: LTZ294
A27: Név
... A46: Beteg
